<?xml version="1.0"?>
<robot name="sphere_skeleton">
    <link name="world" />
    <link
    name="palm">
    <inertial>
      <origin
        xyz="-0 -0.0 -0.0"
        rpy="0 0 0" />
      <mass
        value="1" />
      <inertia
        ixx="0.0001"
        ixy="0"
        ixz="0"
        iyy="0.0001"
        iyz="0"
        izz="0.0001" />
    </inertial>
    <visual>
        <origin
        xyz="-0.025 -0.025 -0.025"
        rpy="0 0 0" />
      <!--<origin-->
        <!--xyz="-0.01 -0.032 -0.032"-->
        <!--rpy="0 0 0" />-->
      <geometry>
          <!--<sphere-->
          <!--radius="0.02" />-->
        <mesh
          filename="meshes/sphere.STL" />
      </geometry>
      <material
        name="">
        <color
          rgba="0.792156862745098 0.819607843137255 0.933333333333333 1" />
      </material>
    </visual>
    <collision>
        <origin
        xyz="-0.025 -0.025 -0.025"
        rpy="0 0 0" />
      <!--<origin-->
        <!--xyz="-0.01 -0.032 -0.032"-->
        <!--rpy="0 0 0" />-->
      <geometry>
          <!--<sphere-->
          <!--radius="0.02" />-->
        <mesh
          filename="meshes/sphere.STL" />
      </geometry>
    </collision>
  </link>
        <joint name="ground_joint" type="floating">
        <origin xyz="0 0 0"/>
        <parent link="world" />
        <child link="palm" />
        <!--<axis xyz="0 1 0 "/>-->
    </joint>
</robot>
